Traceback (most recent call last):
  File "<frozen runpy>", line 198, in _run_module_as_main
  File "<frozen runpy>", line 88, in _run_code
  File "/home/fracchio/.espressif/python_env/idf5.2_py3.11_env/lib64/python3.11/site-packages/esptool/__main__.py", line 9, in <module>
    esptool._main()
  File "/home/fracchio/.espressif/python_env/idf5.2_py3.11_env/lib64/python3.11/site-packages/esptool/__init__.py", line 1139, in _main
    main()
  File "/home/fracchio/.espressif/python_env/idf5.2_py3.11_env/lib64/python3.11/site-packages/esptool/__init__.py", line 936, in main
    esp.hard_reset()
  File "/home/fracchio/.espressif/python_env/idf5.2_py3.11_env/lib64/python3.11/site-packages/esptool/targets/esp32s3.py", line 347, in hard_reset
    HardReset(self._port, uses_usb_otg)()
  File "/home/fracchio/.espressif/python_env/idf5.2_py3.11_env/lib64/python3.11/site-packages/esptool/reset.py", line 125, in __call__
    self._setRTS(True)  # EN->LOW
    ^^^^^^^^^^^^^^^^^^
  File "/home/fracchio/.espressif/python_env/idf5.2_py3.11_env/lib64/python3.11/site-packages/esptool/reset.py", line 44, in _setRTS
    self.port.setDTR(self.port.dtr)
  File "/home/fracchio/.espressif/python_env/idf5.2_py3.11_env/lib64/python3.11/site-packages/serial/serialutil.py", line 603, in setDTR
    self.dtr = value
    ^^^^^^^^
  File "/home/fracchio/.espressif/python_env/idf5.2_py3.11_env/lib64/python3.11/site-packages/serial/serialutil.py", line 473, in dtr
    self._update_dtr_state()
  File "/home/fracchio/.espressif/python_env/idf5.2_py3.11_env/lib64/python3.11/site-packages/serial/serialposix.py", line 715, in _update_dtr_state
    fcntl.ioctl(self.fd, TIOCMBIC, TIOCM_DTR_str)
TimeoutError: [Errno 110] Connection timed out
CMake Error at run_serial_tool.cmake:66 (message):
  
  /home/fracchio/.espressif/python_env/idf5.2_py3.11_env/bin/python;;/home/fracchio/esp/esp-idf/components/esptool_py/esptool/esptool.py;--chip;esp32s3
  failed.



